{"trial_id": "00", "hyperparameters": {"space": [{"class_name": "Int", "config": {"name": "lstm_units", "default": null, "conditions": [], "min_value": 32, "max_value": 256, "step": 32, "sampling": "linear"}}, {"class_name": "Int", "config": {"name": "dense_units", "default": null, "conditions": [], "min_value": 32, "max_value": 128, "step": 32, "sampling": "linear"}}, {"class_name": "Float", "config": {"name": "dropout_rate", "default": 0.1, "conditions": [], "min_value": 0.1, "max_value": 0.5, "step": 0.1, "sampling": "linear"}}, {"class_name": "Float", "config": {"name": "learning_rate", "default": 0.0001, "conditions": [], "min_value": 0.0001, "max_value": 0.01, "step": null, "sampling": "log"}}], "values": {"lstm_units": 192, "dense_units": 64, "dropout_rate": 0.5, "learning_rate": 0.0024582322316185896}}, "metrics": {"metrics": {}}, "score": null, "best_step": 0, "status": "FAILED", "message": "Traceback (most recent call last):\n  File \"C:\\Users\\landr\\miniconda3\\envs\\me423\\lib\\site-packages\\keras_tuner\\src\\engine\\base_tuner.py\", line 274, in _try_run_and_update_trial\n    self._run_and_update_trial(trial, *fit_args, **fit_kwargs)\n  File \"C:\\Users\\landr\\miniconda3\\envs\\me423\\lib\\site-packages\\keras_tuner\\src\\engine\\base_tuner.py\", line 239, in _run_and_update_trial\n    results = self.run_trial(trial, *fit_args, **fit_kwargs)\n  File \"C:\\Users\\landr\\miniconda3\\envs\\me423\\lib\\site-packages\\keras_tuner\\src\\engine\\tuner.py\", line 314, in run_trial\n    obj_value = self._build_and_fit_model(trial, *args, **copied_kwargs)\n  File \"C:\\Users\\landr\\miniconda3\\envs\\me423\\lib\\site-packages\\keras_tuner\\src\\engine\\tuner.py\", line 233, in _build_and_fit_model\n    results = self.hypermodel.fit(hp, model, *args, **kwargs)\n  File \"C:\\Users\\landr\\miniconda3\\envs\\me423\\lib\\site-packages\\keras_tuner\\src\\engine\\hypermodel.py\", line 149, in fit\n    return model.fit(*args, **kwargs)\n  File \"C:\\Users\\landr\\miniconda3\\envs\\me423\\lib\\site-packages\\keras\\src\\utils\\traceback_utils.py\", line 122, in error_handler\n    raise e.with_traceback(filtered_tb) from None\n  File \"C:\\Users\\landr\\miniconda3\\envs\\me423\\lib\\site-packages\\keras\\src\\utils\\traceback_utils.py\", line 122, in error_handler\n    raise e.with_traceback(filtered_tb) from None\nValueError: Exception encountered when calling Normalization.call().\n\n\u001b[1mDimensions must be equal, but are 157 and 9 for '{{node functional_1/normalization_1/Sub}} = Sub[T=DT_FLOAT](functional_1/concatenate_1/concat, functional_1/normalization_1/Sub/y)' with input shapes: [16,15,157], [1,9].\u001b[0m\n\nArguments received by Normalization.call():\n  \u2022 inputs=tf.Tensor(shape=(16, 15, 157), dtype=float32)\n"}